# py_exception_exp2
